Workbook

Sheet Matriz Criterios
A1: MATRIZ DE SELECCIÓN DE CRITERIOS DE EVALUACIÓN POR TAREA — SOSTENIBILIDAD (1º DAW / DAM)
A2: Marca con una 'X' en la casilla correspondiente para activar los criterios evaluados en cada tarea. Las filas 41 y 42 se calculan automáticamente.
A4: CRITERIOS OFICIALES DE EVALUACIÓN (RD 659/2023 ANEXO VIII & DECRETO 104/2024) | H4: 1er TRIMESTRE (T1) — ASG & RETOS | L4: 2º TRIMESTRE (T2) — CIRCULAR & GREEN IT | P4: 3er TRIMESTRE (T3) — PLAN & REPORTE | T4: Pond. CE Oficial
A5: RA | B5: Peso RA | C5: Código CE | D5: Descripción Oficial del Criterio de Evaluación | E5: UDs | F5: Total Tareas | G5: Estado Cobertura | H5: T01 Fundamentos ASG | I5: T02 Retos Sector TIC | J5: T03 Proyecto Mapa ASG | K5: T04 Debate & Actitud T1 | L5: T05 Economía Circular | M5: T06 Green IT & Huella | N5: T07 Proyecto Ecodiseño | O5: T08 Rigor & Actitud T2 | P5: T09 Estándares GRI | Q5: T10 KPIs Sostenibilidad | R5: T11 Plan Sostenibilidad | S5: T12 Vinculación Dual T3
A6: RA1 | B6: 0.18 | C6: CE1.a | D6: Se ha descrito el concepto de sostenibilidad y los marcos internacionales. | E6: UD01 | F6: =COUNTIF(H6:S6, "X") | G6: =IF(F6>0, "EVALUADO", "SIN EVALUAR") | H6: X | J6: X | T6: 0.03
A7: RA1 | B7: 0.18 | C7: CE1.b | D7: Se han identificado los asuntos ASG en las organizaciones TIC. | E7: UD02 | F7: =COUNTIF(H7:S7, "X") | G7: =IF(F7>0, "EVALUADO", "SIN EVALUAR") | H7: X | J7: X | K7: X | T7: 0.03
A8: RA1 | B8: 0.18 | C8: CE1.c | D8: Se han relacionado los ODS con la Agenda 2030 en el sector tecnológico. | E8: UD01 | F8: =COUNTIF(H8:S8, "X") | G8: =IF(F8>0, "EVALUADO", "SIN EVALUAR") | H8: X | J8: X | T8: 0.03
A9: RA1 | B9: 0.18 | C9: CE1.d | D9: Se ha analizado la relevancia de los ASG para los grupos de interés (riesgos/oportunidades). | E9: UD02 | F9: =COUNTIF(H9:S9, "X") | G9: =IF(F9>0, "EVALUADO", "SIN EVALUAR") | J9: X | R9: X | T9: 0.03
A10: RA1 | B10: 0.18 | C10: CE1.e | D10: Se han identificado estándares de métricas e información (ISO, GRI, SASB, CSRD). | E10: UD03 | F10: =COUNTIF(H10:S10, "X") | G10: =IF(F10>0, "EVALUADO", "SIN EVALUAR") | H10: X | J10: X | P10: X | T10: 0.03
A11: RA1 | B11: 0.18 | C11: CE1.f | D11: Se ha descrito la inversión socialmente responsable (ISR) y las agencias ESG. | E11: UD03 | F11: =COUNTIF(H11:S11, "X") | G11: =IF(F11>0, "EVALUADO", "SIN EVALUAR") | H11: X | J11: X | T11: 0.03
A12: RA2 | B12: 0.15 | C12: CE2.a | D12: Se han identificado los principales retos ambientales y sociales del sector TIC. | E12: UD04 | F12: =COUNTIF(H12:S12, "X") | G12: =IF(F12>0, "EVALUADO", "SIN EVALUAR") | I12: X | J12: X | T12: 0.03
A13: RA2 | B13: 0.15 | C13: CE2.b | D13: Se han relacionado los retos con la actividad económica y digital. | E13: UD04 | F13: =COUNTIF(H13:S13, "X") | G13: =IF(F13>0, "EVALUADO", "SIN EVALUAR") | I13: X | J13: X | T13: 0.03
A14: RA2 | B14: 0.15 | C14: CE2.c | D14: Se ha analizado el impacto ambiental y social sobre personas y sectores productivos. | E14: UD04 | F14: =COUNTIF(H14:S14, "X") | G14: =IF(F14>0, "EVALUADO", "SIN EVALUAR") | I14: X | J14: X | T14: 0.03
A15: RA2 | B15: 0.15 | C15: CE2.d | D15: Se han identificado medidas y acciones para minimizar impactos. | E15: UD04 | F15: =COUNTIF(H15:S15, "X") | G15: =IF(F15>0, "EVALUADO", "SIN EVALUAR") | I15: X | J15: X | R15: X | T15: 0.03
A16: RA2 | B16: 0.15 | C16: CE2.e | D16: Se ha analizado la importancia de alianzas transversales (ODS 17). | E16: UD01, UD04 | F16: =COUNTIF(H16:S16, "X") | G16: =IF(F16>0, "EVALUADO", "SIN EVALUAR") | J16: X | K16: X | R16: X | T16: 0.03
A17: RA3 | B17: 0.09 | C17: CE3.a | D17: Se han identificado los ODS más relevantes para la actividad profesional TIC. | E17: UD01, UD04 | F17: =COUNTIF(H17:S17, "X") | G17: =IF(F17>0, "EVALUADO", "SIN EVALUAR") | I17: X | J17: X | T17: 0.03
A18: RA3 | B18: 0.09 | C18: CE3.b | D18: Se han analizado los riesgos y oportunidades de los ODS en informática. | E18: UD04 | F18: =COUNTIF(H18:S18, "X") | G18: =IF(F18>0, "EVALUADO", "SIN EVALUAR") | I18: X | J18: X | T18: 0.03
A19: RA3 | B19: 0.09 | C19: CE3.c | D19: Se han identificado acciones prácticas para retos ambientales/sociales personal y laboral. | E19: UD04, UD06 | F19: =COUNTIF(H19:S19, "X") | G19: =IF(F19>0, "EVALUADO", "SIN EVALUAR") | J19: X | K19: X | M19: X | S19: X | T19: 0.03
A20: RA4 | B20: 0.18 | C20: CE4.a | D20: Se ha caracterizado el modelo de producción y consumo lineal frente al circular. | E20: UD05 | F20: =COUNTIF(H20:S20, "X") | G20: =IF(F20>0, "EVALUADO", "SIN EVALUAR") | L20: X | N20: X | T20: 0.03
A21: RA4 | B21: 0.18 | C21: CE4.b | D21: Se han identificado los principios de la economía verde y circular. | E21: UD05 | F21: =COUNTIF(H21:S21, "X") | G21: =IF(F21>0, "EVALUADO", "SIN EVALUAR") | L21: X | N21: X | T21: 0.03
A22: RA4 | B22: 0.18 | C22: CE4.c | D22: Se han contrastado los beneficios de la economía circular frente al modelo clásico. | E22: UD05 | F22: =COUNTIF(H22:S22, "X") | G22: =IF(F22>0, "EVALUADO", "SIN EVALUAR") | L22: X | N22: X | T22: 0.03
A23: RA4 | B23: 0.18 | C23: CE4.d | D23: Se han aplicado principios de ecodiseño (hardware y software). | E23: UD05, UD06 | F23: =COUNTIF(H23:S23, "X") | G23: =IF(F23>0, "EVALUADO", "SIN EVALUAR") | L23: X | N23: X | O23: X | T23: 0.03
A24: RA4 | B24: 0.18 | C24: CE4.e | D24: Se ha analizado el ciclo de vida del producto TIC (LCA/ACV). | E24: UD05 | F24: =COUNTIF(H24:S24, "X") | G24: =IF(F24>0, "EVALUADO", "SIN EVALUAR") | N24: X | R24: X | T24: 0.03
A25: RA4 | B25: 0.18 | C25: CE4.f | D25: Se han identificado procesos productivos y criterios de sostenibilidad aplicados. | E25: UD05, UD06 | F25: =COUNTIF(H25:S25, "X") | G25: =IF(F25>0, "EVALUADO", "SIN EVALUAR") | N25: X | R25: X | T25: 0.03
A26: RA5 | B26: 0.18 | C26: CE5.a | D26: Se ha caracterizado el modelo de consumo actual. | E26: UD05 | F26: =COUNTIF(H26:S26, "X") | G26: =IF(F26>0, "EVALUADO", "SIN EVALUAR") | L26: X | T26: 0.02
A27: RA5 | B27: 0.18 | C27: CE5.b | D27: Se han identificado principios de economía verde/circular. | E27: UD05 | F27: =COUNTIF(H27:S27, "X") | G27: =IF(F27>0, "EVALUADO", "SIN EVALUAR") | L27: X | T27: 0.02
A28: RA5 | B28: 0.18 | C28: CE5.c | D28: Se han contrastado los beneficios del modelo circular. | E28: UD05 | F28: =COUNTIF(H28:S28, "X") | G28: =IF(F28>0, "EVALUADO", "SIN EVALUAR") | L28: X | M28: X | T28: 0.02
A29: RA5 | B29: 0.18 | C29: CE5.d | D29: Se ha evaluado el impacto de actividades personales y profesionales (huella digital). | E29: UD06 | F29: =COUNTIF(H29:S29, "X") | G29: =IF(F29>0, "EVALUADO", "SIN EVALUAR") | M29: X | N29: X | O29: X | T29: 0.02
A30: RA5 | B30: 0.18 | C30: CE5.e | D30: Se han aplicado principios de ecodiseño. | E30: UD05, UD06 | F30: =COUNTIF(H30:S30, "X") | G30: =IF(F30>0, "EVALUADO", "SIN EVALUAR") | N30: X | T30: 0.02
A31: RA5 | B31: 0.18 | C31: CE5.f | D31: Se han aplicado estrategias sostenibles (Green IT, cloud verde, eficiencia energética). | E31: UD06 | F31: =COUNTIF(H31:S31, "X") | G31: =IF(F31>0, "EVALUADO", "SIN EVALUAR") | M31: X | N31: X | R31: X | S31: X | T31: 0.02
A32: RA5 | B32: 0.18 | C32: CE5.g | D32: Se ha analizado el ciclo de vida. | E32: UD05 | F32: =COUNTIF(H32:S32, "X") | G32: =IF(F32>0, "EVALUADO", "SIN EVALUAR") | M32: X | N32: X | T32: 0.02
A33: RA5 | B33: 0.18 | C33: CE5.h | D33: Se han identificado procesos productivos sostenibles. | E33: UD06 | F33: =COUNTIF(H33:S33, "X") | G33: =IF(F33>0, "EVALUADO", "SIN EVALUAR") | N33: X | R33: X | T33: 0.02
A34: RA5 | B34: 0.18 | C34: CE5.i | D34: Se ha aplicado la normativa ambiental (RAEE, Ley 7/2022, LECA, ESPR). | E34: UD06 | F34: =COUNTIF(H34:S34, "X") | G34: =IF(F34>0, "EVALUADO", "SIN EVALUAR") | L34: X | M34: X | N34: X | T34: 0.02
A35: RA6 | B35: 0.22 | C35: CE6.a | D35: Se han identificado los principales grupos de interés de la empresa TIC (stakeholders). | E35: UD07, UD09 | F35: =COUNTIF(H35:S35, "X") | G35: =IF(F35>0, "EVALUADO", "SIN EVALUAR") | P35: X | R35: X | S35: X | T35: 0.044
A36: RA6 | B36: 0.22 | C36: CE6.b | D36: Se han analizado los aspectos ASG materiales y la matriz de doble materialidad. | E36: UD07 | F36: =COUNTIF(H36:S36, "X") | G36: =IF(F36>0, "EVALUADO", "SIN EVALUAR") | P36: X | R36: X | T36: 0.044
A37: RA6 | B37: 0.22 | C37: CE6.c | D37: Se han definido acciones de mitigación de impactos negativos y oportunidades. | E37: UD07 | F37: =COUNTIF(H37:S37, "X") | G37: =IF(F37>0, "EVALUADO", "SIN EVALUAR") | Q37: X | R37: X | S37: X | T37: 0.044
A38: RA6 | B38: 0.22 | C38: CE6.d | D38: Se han determinado métricas e indicadores de desempeño (GRI, ESRS, PUE, SCI). | E38: UD07, UD08 | F38: =COUNTIF(H38:S38, "X") | G38: =IF(F38>0, "EVALUADO", "SIN EVALUAR") | Q38: X | R38: X | T38: 0.044
A39: RA6 | B39: 0.22 | C39: CE6.e | D39: Se ha elaborado un informe formal de sostenibilidad con el plan propuesto. | E39: UD07, UD08 | F39: =COUNTIF(H39:S39, "X") | G39: =IF(F39>0, "EVALUADO", "SIN EVALUAR") | R39: X | T39: 0.044
A40: TOTAL CRITERIOS EVALUADOS POR ESTA TAREA | H40: =COUNTIF(H$6:H$39, "X") | I40: =COUNTIF(I$6:I$39, "X") | J40: =COUNTIF(J$6:J$39, "X") | K40: =COUNTIF(K$6:K$39, "X") | L40: =COUNTIF(L$6:L$39, "X") | M40: =COUNTIF(M$6:M$39, "X") | N40: =COUNTIF(N$6:N$39, "X") | O40: =COUNTIF(O$6:O$39, "X") | ... S40: =COUNTIF(S$6:S$39, "X") | T40: 100.0%
A41: SUMA DE CRITERIOS EVALUADOS EN ESTA TAREA (Suma Directa con 'X') | H41: =SUMIF(H$6:H$39, "X", $T$6:$T$39) | I41: =SUMIF(I$6:I$39, "X", $T$6:$T$39) | J41: =SUMIF(J$6:J$39, "X", $T$6:$T$39) | K41: =SUMIF(K$6:K$39, "X", $T$6:$T$39) | L41: =SUMIF(L$6:L$39, "X", $T$6:$T$39) | M41: =SUMIF(M$6:M$39, "X", $T$6:$T$39) | N41: =SUMIF(N$6:N$39, "X", $T$6:$T$39) | O41: =SUMIF(O$6:O$39, "X", $T$6:$T$39) | ... S41: =SUMIF(S$6:S$39, "X", $T$6:$T$39) | T41: =SUM(H41:S41)
...

Sheet Registro Notas
A1: REGISTRO DE CALIFICACIONES POR TAREA — SOSTENIBILIDAD (1º DAW / DAM)
A2: Introduce las notas obtenidas (0 a 10). Las columnas trimestrales y finales calculan los resultados con los pesos derivados dinámicamente de 'Matriz Criterios'.
A4: DATOS DEL ALUMNADO | D4: 1er TRIMESTRE (T1) | H4: 2º TRIMESTRE (T2) | L4: 3er TRIMESTRE (T3) | P4: CALIFICACIONES TRIMESTRALES Y MEDIA
A5: Nº | B5: Apellidos, Nombre | C5: Grupo | D5: T01 Fundam. ASG | E5: T02 Retos TIC | F5: T03 Proy. Mapa | G5: T04 Debate T1 | H5: T05 Circularidad | I5: T06 Green IT | J5: T07 Proy. Ecodiseño | K5: T08 Rigor T2 | L5: T09 Reporte GRI | M5: T10 KPIs PUE | N5: T11 Plan CSRD | O5: T12 Dual & Ética | P5: 1º TRIMESTRE (100% T1) | Q5: 2º TRIMESTRE (100% T2) | R5: 3er TRIMESTRE (100% T3) | S5: MEDIA CONTINUA (Trimestres)
A6: 1 | B6: Álvarez Gómez, Laura | C6: 1º DAW/M | D6: 8.5 | E6: 9 | F6: 8.5 | G6: 9 | H6: 8.5 | I6: 9 | J6: 8.5 | K6: 9.5 | L6: 9 | M6: 8.5 | N6: 9 | O6: 9.5 | P6: =D6*'Matriz Criterios'!H$42 + E6*'Matriz Criterios'!I$42 + F6*'Matriz Criterios'!J$42 + G6*'Matriz Criterios'!K$42 | Q6: =H6*'Matriz Criterios'!L$42 + I6*'Matriz Criterios'!M$42 + J6*'Matriz Criterios'!N$42 + K6*'Matriz Criterios'!O$42 | R6: =L6*'Matriz Criterios'!P$42 + M6*'Matriz Criterios'!Q$42 + N6*'Matriz Criterios'!R$42 + O6*'Matriz Criterios'!S$42 | S6: =AVERAGE(P6, Q6, R6)
A7: 2 | B7: Benítez Romero, Carlos | C7: 1º DAW/M | D7: 6 | E7: 6.5 | F7: 6 | G7: 7 | H7: 6.5 | I7: 6 | J7: 6.5 | K7: 7 | L7: 6 | M7: 6.5 | N7: 6 | O7: 7 | P7: =D7*'Matriz Criterios'!H$42 + E7*'Matriz Criterios'!I$42 + F7*'Matriz Criterios'!J$42 + G7*'Matriz Criterios'!K$42 | Q7: =H7*'Matriz Criterios'!L$42 + I7*'Matriz Criterios'!M$42 + J7*'Matriz Criterios'!N$42 + K7*'Matriz Criterios'!O$42 | R7: =L7*'Matriz Criterios'!P$42 + M7*'Matriz Criterios'!Q$42 + N7*'Matriz Criterios'!R$42 + O7*'Matriz Criterios'!S$42 | S7: =AVERAGE(P7, Q7, R7)
A8: 3 | B8: Castillo Morales, Elena | C8: 1º DAW/M | D8: 9.5 | E8: 9.5 | F8: 10 | G8: 10 | H8: 10 | I8: 9.5 | J8: 10 | K8: 10 | L8: 9.5 | M8: 10 | N8: 10 | O8: 10 | P8: =D8*'Matriz Criterios'!H$42 + E8*'Matriz Criterios'!I$42 + F8*'Matriz Criterios'!J$42 + G8*'Matriz Criterios'!K$42 | Q8: =H8*'Matriz Criterios'!L$42 + I8*'Matriz Criterios'!M$42 + J8*'Matriz Criterios'!N$42 + K8*'Matriz Criterios'!O$42 | R8: =L8*'Matriz Criterios'!P$42 + M8*'Matriz Criterios'!Q$42 + N8*'Matriz Criterios'!R$42 + O8*'Matriz Criterios'!S$42 | S8: =AVERAGE(P8, Q8, R8)
A9: 4 | B9: Delgado Santos, Alejandro | C9: 1º DAW/M | D9: 4.5 | E9: 5 | F9: 4.5 | G9: 6 | H9: 5 | I9: 4.5 | J9: 4.5 | K9: 5.5 | L9: 5 | M9: 4.5 | N9: 4 | O9: 5 | P9: =D9*'Matriz Criterios'!H$42 + E9*'Matriz Criterios'!I$42 + F9*'Matriz Criterios'!J$42 + G9*'Matriz Criterios'!K$42 | Q9: =H9*'Matriz Criterios'!L$42 + I9*'Matriz Criterios'!M$42 + J9*'Matriz Criterios'!N$42 + K9*'Matriz Criterios'!O$42 | R9: =L9*'Matriz Criterios'!P$42 + M9*'Matriz Criterios'!Q$42 + N9*'Matriz Criterios'!R$42 + O9*'Matriz Criterios'!S$42 | S9: =AVERAGE(P9, Q9, R9)
A10: 5 | B10: Fernández Navarro, Lucía | C10: 1º DAW/M | D10: 7.5 | E10: 8 | F10: 7.5 | G10: 8.5 | H10: 7.5 | I10: 8 | J10: 7.5 | K10: 8.5 | L10: 8 | M10: 7.5 | N10: 8 | O10: 8.5 | P10: =D10*'Matriz Criterios'!H$42 + E10*'Matriz Criterios'!I$42 + F10*'Matriz Criterios'!J$42 + G10*'Matriz Criterios'!K$42 | Q10: =H10*'Matriz Criterios'!L$42 + I10*'Matriz Criterios'!M$42 + J10*'Matriz Criterios'!N$42 + K10*'Matriz Criterios'!O$42 | R10: =L10*'Matriz Criterios'!P$42 + M10*'Matriz Criterios'!Q$42 + N10*'Matriz Criterios'!R$42 + O10*'Matriz Criterios'!S$42 | S10: =AVERAGE(P10, Q10, R10)
A11: 6 | B11: García Serrano, David | C11: 1º DAW/M | D11: 8 | E11: 8.5 | F11: 8 | G11: 8.5 | H11: 8 | I11: 8.5 | J11: 8 | K11: 8.5 | L11: 8.5 | M11: 8 | N11: 8.5 | O11: 8.5 | P11: =D11*'Matriz Criterios'!H$42 + E11*'Matriz Criterios'!I$42 + F11*'Matriz Criterios'!J$42 + G11*'Matriz Criterios'!K$42 | Q11: =H11*'Matriz Criterios'!L$42 + I11*'Matriz Criterios'!M$42 + J11*'Matriz Criterios'!N$42 + K11*'Matriz Criterios'!O$42 | R11: =L11*'Matriz Criterios'!P$42 + M11*'Matriz Criterios'!Q$42 + N11*'Matriz Criterios'!R$42 + O11*'Matriz Criterios'!S$42 | S11: =AVERAGE(P11, Q11, R11)
A12: 7 | B12: Herrera Cruz, Marta | C12: 1º DAW/M | D12: 9 | E12: 9 | F12: 9.5 | G12: 9.5 | H12: 9 | I12: 9.5 | J12: 9 | K12: 9.5 | L12: 9.5 | M12: 9 | N12: 9.5 | O12: 9.5 | P12: =D12*'Matriz Criterios'!H$42 + E12*'Matriz Criterios'!I$42 + F12*'Matriz Criterios'!J$42 + G12*'Matriz Criterios'!K$42 | Q12: =H12*'Matriz Criterios'!L$42 + I12*'Matriz Criterios'!M$42 + J12*'Matriz Criterios'!N$42 + K12*'Matriz Criterios'!O$42 | R12: =L12*'Matriz Criterios'!P$42 + M12*'Matriz Criterios'!Q$42 + N12*'Matriz Criterios'!R$42 + O12*'Matriz Criterios'!S$42 | S12: =AVERAGE(P12, Q12, R12)
A13: 8 | B13: Jiménez Ortiz, Pablo | C13: 1º DAW/M | D13: 5.5 | E13: 5.5 | F13: 6 | G13: 6.5 | H13: 5.5 | I13: 6 | J13: 5.5 | K13: 6.5 | L13: 6 | M13: 5.5 | N13: 5.5 | O13: 6.5 | P13: =D13*'Matriz Criterios'!H$42 + E13*'Matriz Criterios'!I$42 + F13*'Matriz Criterios'!J$42 + G13*'Matriz Criterios'!K$42 | Q13: =H13*'Matriz Criterios'!L$42 + I13*'Matriz Criterios'!M$42 + J13*'Matriz Criterios'!N$42 + K13*'Matriz Criterios'!O$42 | R13: =L13*'Matriz Criterios'!P$42 + M13*'Matriz Criterios'!Q$42 + N13*'Matriz Criterios'!R$42 + O13*'Matriz Criterios'!S$42 | S13: =AVERAGE(P13, Q13, R13)
A14: 9 | B14: López Molina, Sara | C14: 1º DAW/M | D14: 10 | E14: 9.5 | F14: 10 | G14: 10 | H14: 10 | I14: 9.5 | J14: 10 | K14: 10 | L14: 10 | M14: 9.5 | N14: 10 | O14: 10 | P14: =D14*'Matriz Criterios'!H$42 + E14*'Matriz Criterios'!I$42 + F14*'Matriz Criterios'!J$42 + G14*'Matriz Criterios'!K$42 | Q14: =H14*'Matriz Criterios'!L$42 + I14*'Matriz Criterios'!M$42 + J14*'Matriz Criterios'!N$42 + K14*'Matriz Criterios'!O$42 | R14: =L14*'Matriz Criterios'!P$42 + M14*'Matriz Criterios'!Q$42 + N14*'Matriz Criterios'!R$42 + O14*'Matriz Criterios'!S$42 | S14: =AVERAGE(P14, Q14, R14)
A15: 10 | B15: Martín Vega, Javier | C15: 1º DAW/M | D15: 3.5 | E15: 4 | F15: 4 | G15: 5 | H15: 4 | I15: 4.5 | J15: 4 | K15: 4.5 | L15: 4 | M15: 4 | N15: 4 | O15: 4.5 | P15: =D15*'Matriz Criterios'!H$42 + E15*'Matriz Criterios'!I$42 + F15*'Matriz Criterios'!J$42 + G15*'Matriz Criterios'!K$42 | Q15: =H15*'Matriz Criterios'!L$42 + I15*'Matriz Criterios'!M$42 + J15*'Matriz Criterios'!N$42 + K15*'Matriz Criterios'!O$42 | R15: =L15*'Matriz Criterios'!P$42 + M15*'Matriz Criterios'!Q$42 + N15*'Matriz Criterios'!R$42 + O15*'Matriz Criterios'!S$42 | S15: =AVERAGE(P15, Q15, R15)
A16: 11 | B16: Navarro Gil, Ana | C16: 1º DAW/M | D16: 8 | E16: 8.5 | F16: 8 | G16: 9 | H16: 8.5 | I16: 8 | J16: 8.5 | K16: 9 | L16: 8 | M16: 8.5 | N16: 8.5 | O16: 9 | P16: =D16*'Matriz Criterios'!H$42 + E16*'Matriz Criterios'!I$42 + F16*'Matriz Criterios'!J$42 + G16*'Matriz Criterios'!K$42 | Q16: =H16*'Matriz Criterios'!L$42 + I16*'Matriz Criterios'!M$42 + J16*'Matriz Criterios'!N$42 + K16*'Matriz Criterios'!O$42 | R16: =L16*'Matriz Criterios'!P$42 + M16*'Matriz Criterios'!Q$42 + N16*'Matriz Criterios'!R$42 + O16*'Matriz Criterios'!S$42 | S16: =AVERAGE(P16, Q16, R16)
A17: 12 | B17: Pérez Rubio, Álvaro | C17: 1º DAW/M | D17: 7 | E17: 7 | F17: 7.5 | G17: 7.5 | H17: 7.5 | I17: 7 | J17: 7.5 | K17: 7.5 | L17: 7 | M17: 7.5 | N17: 7 | O17: 7.5 | P17: =D17*'Matriz Criterios'!H$42 + E17*'Matriz Criterios'!I$42 + F17*'Matriz Criterios'!J$42 + G17*'Matriz Criterios'!K$42 | Q17: =H17*'Matriz Criterios'!L$42 + I17*'Matriz Criterios'!M$42 + J17*'Matriz Criterios'!N$42 + K17*'Matriz Criterios'!O$42 | R17: =L17*'Matriz Criterios'!P$42 + M17*'Matriz Criterios'!Q$42 + N17*'Matriz Criterios'!R$42 + O17*'Matriz Criterios'!S$42 | S17: =AVERAGE(P17, Q17, R17)
... A20: 15 | B20: Torres Lozano, Irene | C20: 1º DAW/M | D20: 9 | E20: 9.5 | F20: 9 | G20: 9.5 | H20: 9.5 | I20: 9 | J20: 9.5 | K20: 10 | L20: 9 | M20: 9.5 | N20: 9.5 | O20: 10 | P20: =D20*'Matriz Criterios'!H$42 + E20*'Matriz Criterios'!I$42 + F20*'Matriz Criterios'!J$42 + G20*'Matriz Criterios'!K$42 | Q20: =H20*'Matriz Criterios'!L$42 + I20*'Matriz Criterios'!M$42 + J20*'Matriz Criterios'!N$42 + K20*'Matriz Criterios'!O$42 | R20: =L20*'Matriz Criterios'!P$42 + M20*'Matriz Criterios'!Q$42 + N20*'Matriz Criterios'!R$42 + O20*'Matriz Criterios'!S$42 | S20: =AVERAGE(P20, Q20, R20)
A21: PROMEDIO DEL GRUPO | D21: =AVERAGE(D6:D20) | E21: =AVERAGE(E6:E20) | F21: =AVERAGE(F6:F20) | G21: =AVERAGE(G6:G20) | H21: =AVERAGE(H6:H20) | I21: =AVERAGE(I6:I20) | J21: =AVERAGE(J6:J20) | K21: =AVERAGE(K6:K20) | ... S21: =AVERAGE(S6:S20)

Sheet Calculo CEs
A1: CALIFICACIÓN DETALLADA POR CRITERIOS DE EVALUACIÓN (CE1.a a CE6.e) — SOSTENIBILIDAD
A2: Cálculo matemático automático: cada criterio se calcula promediando exclusivamente las tareas donde tiene marcada una 'X' en la 'Matriz Criterios'.
A4: ALUMNADO | C4: RA1 (18%) — Aspectos ASG, Desarrollo Sostenible y Marcos Internacionales | I4: RA2 (15%) — Retos Ambientales y Sociales en el Sector TIC | N4: RA3 (9%) — Criterios Personales y Profesionales | Q4: RA4 (18%) — Economía Circular y Ecodiseño TIC | W4: RA5 (18%) — Actividades Sostenibles, Green IT y Normativa RAEE | AF4: RA6 (22%) — Plan de Sostenibilidad e Informe CSRD/GRI | AK4: RESUMEN DE CRITERIOS
A5: Nº | B5: Apellidos, Nombre | C5: CE1.a | D5: CE1.b | E5: CE1.c | F5: CE1.d | G5: CE1.e | H5: CE1.f | I5: CE2.a | J5: CE2.b | K5: CE2.c | L5: CE2.d | M5: CE2.e | N5: CE3.a | O5: CE3.b | P5: CE3.c | Q5: CE4.a | R5: CE4.b | S5: CE4.c | T5: CE4.d | U5: CE4.e | V5: CE4.f | W5: CE5.a | X5: CE5.b | Y5: CE5.c | Z5: CE5.d | AA5: CE5.e | AB5: CE5.f | AC5: CE5.g | AD5: CE5.h | AE5: CE5.i | AF5: CE6.a | AG5: CE6.b | AH5: CE6.c | AI5: CE6.d | AJ5: CE6.e | AK5: Media CEs Superados | AL5: Nº CEs >= 5 (de 34)
A6: 1 | B6: Álvarez Gómez, Laura | C6: =IF(SUMPRODUCT(('Matriz Criterios'!$H$6:$S$6="X")*ISNUMBER('Registro Notas'!$D6:$O6))=0, "-", SUMPRODUCT(('Matriz Criterios'!$H$6:$S$6="X")*ISNUMBER('Registro Notas'!$D6:$O6)*'Registro Notas'!$D6:$O6)/SUMPRODUCT(('Matriz Criterios'!$H$6:$S$6="X")*ISNUMBER('Registro Notas'!$D6:$O6))) | D6: =IF(SUMPRODUCT(('Matriz Criterios'!$H$7:$S$7="X")*ISNUMBER('Registro Notas'!$D6:$O6))=0, "-", SUMPRODUCT(('Matriz Criterios'!$H$7:$S$7="X")*ISNUMBER('Registro Notas'!$D6:$O6)*'Registro Notas'!$D6:$O6)/SUMPRODUCT(('Matriz Criterios'!$H$7:$S$7="X")*ISNUMBER('Registro Notas'!$D6:$O6))) | E6: =IF(SUMPRODUCT(('Matriz Criterios'!$H$8:$S$8="X")*ISNUMBER('Registro Notas'!$D6:$O6))=0, "-", SUMPRODUCT(('Matriz Criterios'!$H$8:$S$8="X")*ISNUMBER('Registro Notas'!$D6:$O6)*'Registro Notas'!$D6:$O6)/SUMPRODUCT(('Matriz Criterios'!$H$8:$S$8="X")*ISNUMBER('Registro Notas'!$D6:$O6))) | F6: =IF(SUMPRODUCT(('Matriz Criterios'!$H$9:$S$9="X")*ISNUMBER('Registro Notas'!$D6:$O6))=0, "-", SUMPRODUCT(('Matriz Criterios'!$H$9:$S$9="X")*ISNUMBER('Registro Notas'!$D6:$O6)*'Registro Notas'!$D6:$O6)/SUMPRODUCT(('Matriz Criterios'!$H$9:$S$9="X")*ISNUMBER('Registro Notas'!$D6:$O6))) | G6: =IF(SUMPRODUCT(('Matriz Criterios'!$H$10:$S$10="X")*ISNUMBER('Registro Notas'!$D6:$O6))=0, "-", SUMPRODUCT(('Matriz Criterios'!$H$10:$S$10="X")*ISNUMBER('Registro Notas'!$D6:$O6)*'Registro Notas'!$D6:$O6)/SUMPRODUCT(('Matriz Criterios'!$H$10:$S$10="X")*ISNUMBER('Registro Notas'!$D6:$O6))) | H6: =IF(SUMPRODUCT(('Matriz Criterios'!$H$11:$S$11="X")*ISNUMBER('Registro Notas'!$D6:$O6))=0, "-", SUMPRODUCT(('Matriz Criterios'!$H$11:$S$11="X")*ISNUMBER('Registro Notas'!$D6:$O6)*'Registro Notas'!$D6:$O6)/SUMPRODUCT(('Matriz Criterios'!$H$11:$S$11="X")*ISNUMBER('Registro Notas'!$D6:$O6))) | I6: =IF(SUMPRODUCT(('Matriz Criterios'!$H$12:$S$12="X")*ISNUMBER('Registro Notas'!$D6:$O6))=0, "-", SUMPRODUCT(('Matriz Criterios'!$H$12:$S$12="X")*ISNUMBER('Registro Notas'!$D6:$O6)*'Registro Notas'!$D6:$O6)/SUMPRODUCT(('Matriz Criterios'!$H$12:$S$12="X")*ISNUMBER('Registro Notas'!$D6:$O6))) | J6: =IF(SUMPRODUCT(('Matriz Criterios'!$H$13:$S$13="X")*ISNUMBER('Registro Notas'!$D6:$O6))=0, "-", SUMPRODUCT(('Matriz Criterios'!$H$13:$S$13="X")*ISNUMBER('Registro Notas'!$D6:$O6)*'Registro Notas'!$D6:$O6)/SUMPRODUCT(('Matriz Criterios'!$H$13:$S$13="X")*ISNUMBER('Registro Notas'!$D6:$O6))) | K6: =IF(SUMPRODUCT(('Matriz Criterios'!$H$14:$S$14="X")*ISNUMBER('Registro Notas'!$D6:$O6))=0, "-", SUMPRODUCT(('Matriz Criterios'!$H$14:$S$14="X")*ISNUMBER('Registro Notas'!$D6:$O6)*'Registro Notas'!$D6:$O6)/SUMPRODUCT(('Matriz Criterios'!$H$14:$S$14="X")*ISNUMBER('Registro Notas'!$D6:$O6))) | L6: =IF(SUMPRODUCT(('Matriz Criterios'!$H$15:$S$15="X")*ISNUMBER('Registro Notas'!$D6:$O6))=0, "-", SUMPRODUCT(('Matriz Criterios'!$H$15:$S$15="X")*ISNUMBER('Registro Notas'!$D6:$O6)*'Registro Notas'!$D6:$O6)/SUMPRODUCT(('Matriz Criterios'!$H$15:$S$15="X")*ISNUMBER('Registro Notas'!$D6:$O6))) | M6: =IF(SUMPRODUCT(('Matriz Criterios'!$H$16:$S$16="X")*ISNUMBER('Registro Notas'!$D6:$O6))=0, "-", SUMPRODUCT(('Matriz Criterios'!$H$16:$S$16="X")*ISNUMBER('Registro Notas'!$D6:$O6)*'Registro Notas'!$D6:$O6)/SUMPRODUCT(('Matriz Criterios'!$H$16:$S$16="X")*ISNUMBER('Registro Notas'!$D6:$O6))) | N6: =IF(SUMPRODUCT(('Matriz Criterios'!$H$17:$S$17="X")*ISNUMBER('Registro Notas'!$D6:$O6))=0, "-", SUMPRODUCT(('Matriz Criterios'!$H$17:$S$17="X")*ISNUMBER('Registro Notas'!$D6:$O6)*'Registro Notas'!$D6:$O6)/SUMPRODUCT(('Matriz Criterios'!$H$17:$S$17="X")*ISNUMBER('Registro Notas'!$D6:$O6))) | O6: =IF(SUMPRODUCT(('Matriz Criterios'!$H$18:$S$18="X")*ISNUMBER('Registro Notas'!$D6:$O6))=0, "-", SUMPRODUCT(('Matriz Criterios'!$H$18:$S$18="X")*ISNUMBER('Registro Notas'!$D6:$O6)*'Registro Notas'!$D6:$O6)/SUMPRODUCT(('Matriz Criterios'!$H$18:$S$18="X")*ISNUMBER('Registro Notas'!$D6:$O6))) | P6: =IF(SUMPRODUCT(('Matriz Criterios'!$H$19:$S$19="X")*ISNUMBER('Registro Notas'!$D6:$O6))=0, "-", SUMPRODUCT(('Matriz Criterios'!$H$19:$S$19="X")*ISNUMBER('Registro Notas'!$D6:$O6)*'Registro Notas'!$D6:$O6)/SUMPRODUCT(('Matriz Criterios'!$H$19:$S$19="X")*ISNUMBER('Registro Notas'!$D6:$O6))) | Q6: =IF(SUMPRODUCT(('Matriz Criterios'!$H$20:$S$20="X")*ISNUMBER('Registro Notas'!$D6:$O6))=0, "-", SUMPRODUCT(('Matriz Criterios'!$H$20:$S$20="X")*ISNUMBER('Registro Notas'!$D6:$O6)*'Registro Notas'!$D6:$O6)/SUMPRODUCT(('Matriz Criterios'!$H$20:$S$20="X")*ISNUMBER('Registro Notas'!$D6:$O6))) | R6: =IF(SUMPRODUCT(('Matriz Criterios'!$H$21:$S$21="X")*ISNUMBER('Registro Notas'!$D6:$O6))=0, "-", SUMPRODUCT(('Matriz Criterios'!$H$21:$S$21="X")*ISNUMBER('Registro Notas'!$D6:$O6)*'Registro Notas'!$D6:$O6)/SUMPRODUCT(('Matriz Criterios'!$H$21:$S$21="X")*ISNUMBER('Registro Notas'!$D6:$O6))) | S6: =IF(SUMPRODUCT(('Matriz Criterios'!$H$22:$S$22="X")*ISNUMBER('Registro Notas'!$D6:$O6))=0, "-", SUMPRODUCT(('Matriz Criterios'!$H$22:$S$22="X")*ISNUMBER('Registro Notas'!$D6:$O6)*'Registro Notas'!$D6:$O6)/SUMPRODUCT(('Matriz Criterios'!$H$22:$S$22="X")*ISNUMBER('Registro Notas'!$D6:$O6))) | T6: =IF(SUMPRODUCT(('Matriz Criterios'!$H$23:$S$23="X")*ISNUMBER('Registro Notas'!$D6:$O6))=0, "-", SUMPRODUCT(('Matriz Criterios'!$H$23:$S$23="X")*ISNUMBER('Registro Notas'!$D6:$O6)*'Registro Notas'!$D6:$O6)/SUMPRODUCT(('Matriz Criterios'!$H$23:$S$23="X")*ISNUMBER('Registro Notas'!$D6:$O6))) | U6: =IF(SUMPRODUCT(('Matriz Criterios'!$H$24:$S$24="X")*ISNUMBER('Registro Notas'!$D6:$O6))=0, "-", SUMPRODUCT(('Matriz Criterios'!$H$24:$S$24="X")*ISNUMBER('Registro Notas'!$D6:$O6)*'Registro Notas'!$D6:$O6)/SUMPRODUCT(('Matriz Criterios'!$H$24:$S$24="X")*ISNUMBER('Registro Notas'!$D6:$O6))) | V6: =IF(SUMPRODUCT(('Matriz Criterios'!$H$25:$S$25="X")*ISNUMBER('Registro Notas'!$D6:$O6))=0, "-", SUMPRODUCT(('Matriz Criterios'!$H$25:$S$25="X")*ISNUMBER('Registro Notas'!$D6:$O6)*'Registro Notas'!$D6:$O6)/SUMPRODUCT(('Matriz Criterios'!$H$25:$S$25="X")*ISNUMBER('Registro Notas'!$D6:$O6))) | W6: =IF(SUMPRODUCT(('Matriz Criterios'!$H$26:$S$26="X")*ISNUMBER('Registro Notas'!$D6:$O6))=0, "-", SUMPRODUCT(('Matriz Criterios'!$H$26:$S$26="X")*ISNUMBER('Registro Notas'!$D6:$O6)*'Registro Notas'!$D6:$O6)/SUMPRODUCT(('Matriz Criterios'!$H$26:$S$26="X")*ISNUMBER('Registro Notas'!$D6:$O6))) | X6: =IF(SUMPRODUCT(('Matriz Criterios'!$H$27:$S$27="X")*ISNUMBER('Registro Notas'!$D6:$O6))=0, "-", SUMPRODUCT(('Matriz Criterios'!$H$27:$S$27="X")*ISNUMBER('Registro Notas'!$D6:$O6)*'Registro Notas'!$D6:$O6)/SUMPRODUCT(('Matriz Criterios'!$H$27:$S$27="X")*ISNUMBER('Registro Notas'!$D6:$O6))) | Y6: =IF(SUMPRODUCT(('Matriz Criterios'!$H$28:$S$28="X")*ISNUMBER('Registro Notas'!$D6:$O6))=0, "-", SUMPRODUCT(('Matriz Criterios'!$H$28:$S$28="X")*ISNUMBER('Registro Notas'!$D6:$O6)*'Registro Notas'!$D6:$O6)/SUMPRODUCT(('Matriz Criterios'!$H$28:$S$28="X")*ISNUMBER('Registro Notas'!$D6:$O6))) | Z6: =IF(SUMPRODUCT(('Matriz Criterios'!$H$29:$S$29="X")*ISNUMBER('Registro Notas'!$D6:$O6))=0, "-", SUMPRODUCT(('Matriz Criterios'!$H$29:$S$29="X")*ISNUMBER('Registro Notas'!$D6:$O6)*'Registro Notas'!$D6:$O6)/SUMPRODUCT(('Matriz Criterios'!$H$29:$S$29="X")*ISNUMBER('Registro Notas'!$D6:$O6))) | AA6: =IF(SUMPRODUCT(('Matriz Criterios'!$H$30:$S$30="X")*ISNUMBER('Registro Notas'!$D6:$O6))=0, "-", SUMPRODUCT(('Matriz Criterios'!$H$30:$S$30="X")*ISNUMBER('Registro Notas'!$D6:$O6)*'Registro Notas'!$D6:$O6)/SUMPRODUCT(('Matriz Criterios'!$H$30:$S$30="X")*ISNUMBER('Registro Notas'!$D6:$O6))) | AB6: =IF(SUMPRODUCT(('Matriz Criterios'!$H$31:$S$31="X")*ISNUMBER('Registro Notas'!$D6:$O6))=0, "-", SUMPRODUCT(('Matriz Criterios'!$H$31:$S$31="X")*ISNUMBER('Registro Notas'!$D6:$O6)*'Registro Notas'!$D6:$O6)/SUMPRODUCT(('Matriz Criterios'!$H$31:$S$31="X")*ISNUMBER('Registro Notas'!$D6:$O6))) | AC6: =IF(SUMPRODUCT(('Matriz Criterios'!$H$32:$S$32="X")*ISNUMBER('Registro Notas'!$D6:$O6))=0, "-", SUMPRODUCT(('Matriz Criterios'!$H$32:$S$32="X")*ISNUMBER('Registro Notas'!$D6:$O6)*'Registro Notas'!$D6:$O6)/SUMPRODUCT(('Matriz Criterios'!$H$32:$S$32="X")*ISNUMBER('Registro Notas'!$D6:$O6))) | AD6: =IF(SUMPRODUCT(('Matriz Criterios'!$H$33:$S$33="X")*ISNUMBER('Registro Notas'!$D6:$O6))=0, "-", SUMPRODUCT(('Matriz Criterios'!$H$33:$S$33="X")*ISNUMBER('Registro Notas'!$D6:$O6)*'Registro Notas'!$D6:$O6)/SUMPRODUCT(('Matriz Criterios'!$H$33:$S$33="X")*ISNUMBER('Registro Notas'!$D6:$O6))) | AE6: =IF(SUMPRODUCT(('Matriz Criterios'!$H$34:$S$34="X")*ISNUMBER('Registro Notas'!$D6:$O6))=0, "-", SUMPRODUCT(('Matriz Criterios'!$H$34:$S$34="X")*ISNUMBER('Registro Notas'!$D6:$O6)*'Registro Notas'!$D6:$O6)/SUMPRODUCT(('Matriz Criterios'!$H$34:$S$34="X")*ISNUMBER('Registro Notas'!$D6:$O6))) | AF6: =IF(SUMPRODUCT(('Matriz Criterios'!$H$35:$S$35="X")*ISNUMBER('Registro Notas'!$D6:$O6))=0, "-", SUMPRODUCT(('Matriz Criterios'!$H$35:$S$35="X")*ISNUMBER('Registro Notas'!$D6:$O6)*'Registro Notas'!$D6:$O6)/SUMPRODUCT(('Matriz Criterios'!$H$35:$S$35="X")*ISNUMBER('Registro Notas'!$D6:$O6))) | AG6: =IF(SUMPRODUCT(('Matriz Criterios'!$H$36:$S$36="X")*ISNUMBER('Registro Notas'!$D6:$O6))=0, "-", SUMPRODUCT(('Matriz Criterios'!$H$36:$S$36="X")*ISNUMBER('Registro Notas'!$D6:$O6)*'Registro Notas'!$D6:$O6)/SUMPRODUCT(('Matriz Criterios'!$H$36:$S$36="X")*ISNUMBER('Registro Notas'!$D6:$O6))) | AH6: =IF(SUMPRODUCT(('Matriz Criterios'!$H$37:$S$37="X")*ISNUMBER('Registro Notas'!$D6:$O6))=0, "-", SUMPRODUCT(('Matriz Criterios'!$H$37:$S$37="X")*ISNUMBER('Registro Notas'!$D6:$O6)*'Registro Notas'!$D6:$O6)/SUMPRODUCT(('Matriz Criterios'!$H$37:$S$37="X")*ISNUMBER('Registro Notas'!$D6:$O6))) | AI6: =IF(SUMPRODUCT(('Matriz Criterios'!$H$38:$S$38="X")*ISNUMBER('Registro Notas'!$D6:$O6))=0, "-", SUMPRODUCT(('Matriz Criterios'!$H$38:$S$38="X")*ISNUMBER('Registro Notas'!$D6:$O6)*'Registro Notas'!$D6:$O6)/SUMPRODUCT(('Matriz Criterios'!$H$38:$S$38="X")*ISNUMBER('Registro Notas'!$D6:$O6))) | AJ6: =IF(SUMPRODUCT(('Matriz Criterios'!$H$39:$S$39="X")*ISNUMBER('Registro Notas'!$D6:$O6))=0, "-", SUMPRODUCT(('Matriz Criterios'!$H$39:$S$39="X")*ISNUMBER('Registro Notas'!$D6:$O6)*'Registro Notas'!$D6:$O6)/SUMPRODUCT(('Matriz Criterios'!$H$39:$S$39="X")*ISNUMBER('Registro Notas'!$D6:$O6))) | AK6: =AVERAGE(C6:AJ6) | AL6: =COUNTIF(C6:AJ6, ">=5")
A7: 2 | B7: Benítez Romero, Carlos | C7: =IF(SUMPRODUCT(('Matriz Criterios'!$H$6:$S$6="X")*ISNUMBER('Registro Notas'!$D7:$O7))=0, "-", SUMPRODUCT(('Matriz Criterios'!$H$6:$S$6="X")*ISNUMBER('Registro Notas'!$D7:$O7)*'Registro Notas'!$D7:$O7)/SUMPRODUCT(('Matriz Criterios'!$H$6:$S$6="X")*ISNUMBER('Registro Notas'!$D7:$O7))) | D7: =IF(SUMPRODUCT(('Matriz Criterios'!$H$7:$S$7="X")*ISNUMBER('Registro Notas'!$D7:$O7))=0, "-", SUMPRODUCT(('Matriz Criterios'!$H$7:$S$7="X")*ISNUMBER('Registro Notas'!$D7:$O7)*'Registro Notas'!$D7:$O7)/SUMPRODUCT(('Matriz Criterios'!$H$7:$S$7="X")*ISNUMBER('Registro Notas'!$D7:$O7))) | E7: =IF(SUMPRODUCT(('Matriz Criterios'!$H$8:$S$8="X")*ISNUMBER('Registro Notas'!$D7:$O7))=0, "-", SUMPRODUCT(('Matriz Criterios'!$H$8:$S$8="X")*ISNUMBER('Registro Notas'!$D7:$O7)*'Registro Notas'!$D7:$O7)/SUMPRODUCT(('Matriz Criterios'!$H$8:$S$8="X")*ISNUMBER('Registro Notas'!$D7:$O7))) | F7: =IF(SUMPRODUCT(('Matriz Criterios'!$H$9:$S$9="X")*ISNUMBER('Registro Notas'!$D7:$O7))=0, "-", SUMPRODUCT(('Matriz Criterios'!$H$9:$S$9="X")*ISNUMBER('Registro Notas'!$D7:$O7)*'Registro Notas'!$D7:$O7)/SUMPRODUCT(('Matriz Criterios'!$H$9:$S$9="X")*ISNUMBER('Registro Notas'!$D7:$O7))) | G7: =IF(SUMPRODUCT(('Matriz Criterios'!$H$10:$S$10="X")*ISNUMBER('Registro Notas'!$D7:$O7))=0, "-", SUMPRODUCT(('Matriz Criterios'!$H$10:$S$10="X")*ISNUMBER('Registro Notas'!$D7:$O7)*'Registro Notas'!$D7:$O7)/SUMPRODUCT(('Matriz Criterios'!$H$10:$S$10="X")*ISNUMBER('Registro Notas'!$D7:$O7))) | H7: =IF(SUMPRODUCT(('Matriz Criterios'!$H$11:$S$11="X")*ISNUMBER('Registro Notas'!$D7:$O7))=0, "-", SUMPRODUCT(('Matriz Criterios'!$H$11:$S$11="X")*ISNUMBER('Registro Notas'!$D7:$O7)*'Registro Notas'!$D7:$O7)/SUMPRODUCT(('Matriz Criterios'!$H$11:$S$11="X")*ISNUMBER('Registro Notas'!$D7:$O7))) | I7: =IF(SUMPRODUCT(('Matriz Criterios'!$H$12:$S$12="X")*ISNUMBER('Registro Notas'!$D7:$O7))=0, "-", SUMPRODUCT(('Matriz Criterios'!$H$12:$S$12="X")*ISNUMBER('Registro Notas'!$D7:$O7)*'Registro Notas'!$D7:$O7)/SUMPRODUCT(('Matriz Criterios'!$H$12:$S$12="X")*ISNUMBER('Registro Notas'!$D7:$O7))) | J7: =IF(SUMPRODUCT(('Matriz Criterios'!$H$13:$S$13="X")*ISNUMBER('Registro Notas'!$D7:$O7))=0, "-", SUMPRODUCT(('Matriz Criterios'!$H$13:$S$13="X")*ISNUMBER('Registro Notas'!$D7:$O7)*'Registro Notas'!$D7:$O7)/SUMPRODUCT(('Matriz Criterios'!$H$13:$S$13="X")*ISNUMBER('Registro Notas'!$D7:$O7))) | K7: =IF(SUMPRODUCT(('Matriz Criterios'!$H$14:$S$14="X")*ISNUMBER('Registro Notas'!$D7:$O7))=0, "-", SUMPRODUCT(('Matriz Criterios'!$H$14:$S$14="X")*ISNUMBER('Registro Notas'!$D7:$O7)*'Registro Notas'!$D7:$O7)/SUMPRODUCT(('Matriz Criterios'!$H$14:$S$14="X")*ISNUMBER('Registro Notas'!$D7:$O7))) | L7: =IF(SUMPRODUCT(('Matriz Criterios'!$H$15:$S$15="X")*ISNUMBER('Registro Notas'!$D7:$O7))=0, "-", SUMPRODUCT(('Matriz Criterios'!$H$15:$S$15="X")*ISNUMBER('Registro Notas'!$D7:$O7)*'Registro Notas'!$D7:$O7)/SUMPRODUCT(('Matriz Criterios'!$H$15:$S$15="X")*ISNUMBER('Registro Notas'!$D7:$O7))) | M7: =IF(SUMPRODUCT(('Matriz Criterios'!$H$16:$S$16="X")*ISNUMBER('Registro Notas'!$D7:$O7))=0, "-", SUMPRODUCT(('Matriz Criterios'!$H$16:$S$16="X")*ISNUMBER('Registro Notas'!$D7:$O7)*'Registro Notas'!$D7:$O7)/SUMPRODUCT(('Matriz Criterios'!$H$16:$S$16="X")*ISNUMBER('Registro Notas'!$D7:$O7))) | N7: =IF(SUMPRODUCT(('Matriz Criterios'!$H$17:$S$17="X")*ISNUMBER('Registro Notas'!$D7:$O7))=0, "-", SUMPRODUCT(('Matriz Criterios'!$H$17:$S$17="X")*ISNUMBER('Registro Notas'!$D7:$O7)*'Registro Notas'!$D7:$O7)/SUMPRODUCT(('Matriz Criterios'!$H$17:$S$17="X")*ISNUMBER('Registro Notas'!$D7:$O7))) | O7: =IF(SUMPRODUCT(('Matriz Criterios'!$H$18:$S$18="X")*ISNUMBER('Registro Notas'!$D7:$O7))=0, "-", SUMPRODUCT(('Matriz Criterios'!$H$18:$S$18="X")*ISNUMBER('Registro Notas'!$D7:$O7)*'Registro Notas'!$D7:$O7)/SUMPRODUCT(('Matriz Criterios'!$H$18:$S$18="X")*ISNUMBER('Registro Notas'!$D7:$O7))) | P7: =IF(SUMPRODUCT(('Matriz Criterios'!$H$19:$S$19="X")*ISNUMBER('Registro Notas'!$D7:$O7))=0, "-", SUMPRODUCT(('Matriz Criterios'!$H$19:$S$19="X")*ISNUMBER('Registro Notas'!$D7:$O7)*'Registro Notas'!$D7:$O7)/SUMPRODUCT(('Matriz Criterios'!$H$19:$S$19="X")*ISNUMBER('Registro Notas'!$D7:$O7))) | Q7: =IF(SUMPRODUCT(('Matriz Criterios'!$H$20:$S$20="X")*ISNUMBER('Registro Notas'!$D7:$O7))=0, "-", SUMPRODUCT(('Matriz Criterios'!$H$20:$S$20="X")*ISNUMBER('Registro Notas'!$D7:$O7)*'Registro Notas'!$D7:$O7)/SUMPRODUCT(('Matriz Criterios'!$H$20:$S$20="X")*ISNUMBER('Registro Notas'!$D7:$O7))) | R7: =IF(SUMPRODUCT(('Matriz Criterios'!$H$21:$S$21="X")*ISNUMBER('Registro Notas'!$D7:$O7))=0, "-", SUMPRODUCT(('Matriz Criterios'!$H$21:$S$21="X")*ISNUMBER('Registro Notas'!$D7:$O7)*'Registro Notas'!$D7:$O7)/SUMPRODUCT(('Matriz Criterios'!$H$21:$S$21="X")*ISNUMBER('Registro Notas'!$D7:$O7))) | S7: =IF(SUMPRODUCT(('Matriz Criterios'!$H$22:$S$22="X")*ISNUMBER('Registro Notas'!$D7:$O7))=0, "-", SUMPRODUCT(('Matriz Criterios'!$H$22:$S$22="X")*ISNUMBER('Registro Notas'!$D7:$O7)*'Registro Notas'!$D7:$O7)/SUMPRODUCT(('Matriz Criterios'!$H$22:$S$22="X")*ISNUMBER('Registro Notas'!$D7:$O7))) | T7: =IF(SUMPRODUCT(('Matriz Criterios'!$H$23:$S$23="X")*ISNUMBER('Registro Notas'!$D7:$O7))=0, "-", SUMPRODUCT(('Matriz Criterios'!$H$23:$S$23="X")*ISNUMBER('Registro Notas'!$D7:$O7)*'Registro Notas'!$D7:$O7)/SUMPRODUCT(('Matriz Criterios'!$H$23:$S$23="X")*ISNUMBER('Registro Notas'!$D7:$O7))) | U7: =IF(SUMPRODUCT(('Matriz Criterios'!$H$24:$S$24="X")*ISNUMBER('Registro Notas'!$D7:$O7))=0, "-", SUMPRODUCT(('Matriz Criterios'!$H$24:$S$24="X")*ISNUMBER('Registro Notas'!$D7:$O7)*'Registro Notas'!$D7:$O7)/SUMPRODUCT(('Matriz Criterios'!$H$24:$S$24="X")*ISNUMBER('Registro Notas'!$D7:$O7))) | V7: =IF(SUMPRODUCT(('Matriz Criterios'!$H$25:$S$25="X")*ISNUMBER('Registro Notas'!$D7:$O7))=0, "-", SUMPRODUCT(('Matriz Criterios'!$H$25:$S$25="X")*ISNUMBER('Registro Notas'!$D7:$O7)*'Registro Notas'!$D7:$O7)/SUMPRODUCT(('Matriz Criterios'!$H$25:$S$25="X")*ISNUMBER('Registro Notas'!$D7:$O7))) | W7: =IF(SUMPRODUCT(('Matriz Criterios'!$H$26:$S$26="X")*ISNUMBER('Registro Notas'!$D7:$O7))=0, "-", SUMPRODUCT(('Matriz Criterios'!$H$26:$S$26="X")*ISNUMBER('Registro Notas'!$D7:$O7)*'Registro Notas'!$D7:$O7)/SUMPRODUCT(('Matriz Criterios'!$H$26:$S$26="X")*ISNUMBER('Registro Notas'!$D7:$O7))) | X7: =IF(SUMPRODUCT(('Matriz Criterios'!$H$27:$S$27="X")*ISNUMBER('Registro Notas'!$D7:$O7))=0, "-", SUMPRODUCT(('Matriz Criterios'!$H$27:$S$27="X")*ISNUMBER('Registro Notas'!$D7:$O7)*'Registro Notas'!$D7:$O7)/SUMPRODUCT(('Matriz Criterios'!$H$27:$S$27="X")*ISNUMBER('Registro Notas'!$D7:$O7))) | Y7: =IF(SUMPRODUCT(('Matriz Criterios'!$H$28:$S$28="X")*ISNUMBER('Registro Notas'!$D7:$O7))=0, "-", SUMPRODUCT(('Matriz Criterios'!$H$28:$S$28="X")*ISNUMBER('Registro Notas'!$D7:$O7)*'Registro Notas'!$D7:$O7)/SUMPRODUCT(('Matriz Criterios'!$H$28:$S$28="X")*ISNUMBER('Registro Notas'!$D7:$O7))) | Z7: =IF(SUMPRODUCT(('Matriz Criterios'!$H$29:$S$29="X")*ISNUMBER('Registro Notas'!$D7:$O7))=0, "-", SUMPRODUCT(('Matriz Criterios'!$H$29:$S$29="X")*ISNUMBER('Registro Notas'!$D7:$O7)*'Registro Notas'!$D7:$O7)/SUMPRODUCT(('Matriz Criterios'!$H$29:$S$29="X")*ISNUMBER('Registro Notas'!$D7:$O7))) | AA7: =IF(SUMPRODUCT(('Matriz Criterios'!$H$30:$S$30="X")*ISNUMBER('Registro Notas'!$D7:$O7))=0, "-", SUMPRODUCT(('Matriz Criterios'!$H$30:$S$30="X")*ISNUMBER('Registro Notas'!$D7:$O7)*'Registro Notas'!$D7:$O7)/SUMPRODUCT(('Matriz Criterios'!$H$30:$S$30="X")*ISNUMBER('Registro Notas'!$D7:$O7))) | AB7: =IF(SUMPRODUCT(('Matriz Criterios'!$H$31:$S$31="X")*ISNUMBER('Registro Notas'!$D7:$O7))=0, "-", SUMPRODUCT(('Matriz Criterios'!$H$31:$S$31="X")*ISNUMBER('Registro Notas'!$D7:$O7)*'Registro Notas'!$D7:$O7)/SUMPRODUCT(('Matriz Criterios'!$H$31:$S$31="X")*ISNUMBER('Registro Notas'!$D7:$O7))) | AC7: =IF(SUMPRODUCT(('Matriz Criterios'!$H$32:$S$32="X")*ISNUMBER('Registro Notas'!$D7:$O7))=0, "-", SUMPRODUCT(('Matriz Criterios'!$H$32:$S$32="X")*ISNUMBER('Registro Notas'!$D7:$O7)*'Registro Notas'!$D7:$O7)/SUMPRODUCT(('Matriz Criterios'!$H$32:$S$32="X")*ISNUMBER('Registro Notas'!$D7:$O7))) | AD7: =IF(SUMPRODUCT(('Matriz Criterios'!$H$33:$S$33="X")*ISNUMBER('Registro Notas'!$D7:$O7))=0, "-", SUMPRODUCT(('Matriz Criterios'!$H$33:$S$33="X")*ISNUMBER('Registro Notas'!$D7:$O7)*'Registro Notas'!$D7:$O7)/SUMPRODUCT(('Matriz Criterios'!$H$33:$S$33="X")*ISNUMBER('Registro Notas'!$D7:$O7))) | AE7: =IF(SUMPRODUCT(('Matriz Criterios'!$H$34:$S$34="X")*ISNUMBER('Registro Notas'!$D7:$O7))=0, "-", SUMPRODUCT(('Matriz Criterios'!$H$34:$S$34="X")*ISNUMBER('Registro Notas'!$D7:$O7)*'Registro Notas'!$D7:$O7)/SUMPRODUCT(('Matriz Criterios'!$H$34:$S$34="X")*ISNUMBER('Registro Notas'!$D7:$O7))) | AF7: =IF(SUMPRODUCT(('Matriz Criterios'!$H$35:$S$35="X")*ISNUMBER('Registro Notas'!$D7:$O7))=0, "-", SUMPRODUCT(('Matriz Criterios'!$H$35:$S$35="X")*ISNUMBER('Registro Notas'!$D7:$O7)*'Registro Notas'!$D7:$O7)/SUMPRODUCT(('Matriz Criterios'!$H$35:$S$35="X")*ISNUMBER('Registro Notas'!$D7:$O7))) | AG7: =IF(SUMPRODUCT(('Matriz Criterios'!$H$36:$S$36="X")*ISNUMBER('Registro Notas'!$D7:$O7))=0, "-", SUMPRODUCT(('Matriz Criterios'!$H$36:$S$36="X")*ISNUMBER('Registro Notas'!$D7:$O7)*'Registro Notas'!$D7:$O7)/SUMPRODUCT(('Matriz Criterios'!$H$36:$S$36="X")*ISNUMBER('Registro Notas'!$D7:$O7))) | AH7: =IF(SUMPRODUCT(('Matriz Criterios'!$H$37:$S$37="X")*ISNUMBER('Registro Notas'!$D7:$O7))=0, "-", SUMPRODUCT(('Matriz Criterios'!$H$37:$S$37="X")*ISNUMBER('Registro Notas'!$D7:$O7)*'Registro Notas'!$D7:$O7)/SUMPRODUCT(('Matriz Criterios'!$H$37:$S$37="X")*ISNUMBER('Registro Notas'!$D7:$O7))) | AI7: =IF(SUMPRODUCT(('Matriz Criterios'!$H$38:$S$38="X")*ISNUMBER('Registro Notas'!$D7:$O7))=0, "-", SUMPRODUCT(('Matriz Criterios'!$H$38:$S$38="X")*ISNUMBER('Registro Notas'!$D7:$O7)*'Registro Notas'!$D7:$O7)/SUMPRODUCT(('Matriz Criterios'!$H$38:$S$38="X")*ISNUMBER('Registro Notas'!$D7:$O7))) | AJ7: =IF(SUMPRODUCT(('Matriz Criterios'!$H$39:$S$39="X")*ISNUMBER('Registro Notas'!$D7:$O7))=0, "-", SUMPRODUCT(('Matriz Criterios'!$H$39:$S$39="X")*ISNUMBER('Registro Notas'!$D7:$O7)*'Registro Notas'!$D7:$O7)/SUMPRODUCT(('Matriz Criterios'!$H$39:$S$39="X")*ISNUMBER('Registro Notas'!$D7:$O7))) | AK7: =AVERAGE(C7:AJ7) | AL7: =COUNTIF(C7:AJ7, ">=5")
A8: 3 | B8: Castillo Morales, Elena | C8: =IF(SUMPRODUCT(('Matriz Criterios'!$H$6:$S$6="X")*ISNUMBER('Registro Notas'!$D8:$O8))=0, "-", SUMPRODUCT(('Matriz Criterios'!$H$6:$S$6="X")*ISNUMBER('Registro Notas'!$D8:$O8)*'Registro Notas'!$D8:$O8)/SUMPRODUCT(('Matriz Criterios'!$H$6:$S$6="X")*ISNUMBER('Registro Notas'!$D8:$O8))) | D8: =IF(SUMPRODUCT(('Matriz Criterios'!$H$7:$S$7="X")*ISNUMBER('Registro Notas'!$D8:$O8))=0, "-", SUMPRODUCT(('Matriz Criterios'!$H$7:$S$7="X")*ISNUMBER('Registro Notas'!$D8:$O8)*'Registro Notas'!$D8:$O8)/SUMPRODUCT(('Matriz Criterios'!$H$7:$S$7="X")*ISNUMBER('Registro Notas'!$D8:$O8))) | E8: =IF(SUMPRODUCT(('Matriz Criterios'!$H$8:$S$8="X")*ISNUMBER('Registro Notas'!$D8:$O8))=0, "-", SUMPRODUCT(('Matriz Criterios'!$H$8:$S$8="X")*ISNUMBER('Registro Notas'!$D8:$O8)*'Registro Notas'!$D8:$O8)/SUMPRODUCT(('Matriz Criterios'!$H$8:$S$8="X")*ISNUMBER('Registro Notas'!$D8:$O8))) | F8: =IF(SUMPRODUCT(('Matriz Criterios'!$H$9:$S$9="X")*ISNUMBER('Registro Notas'!$D8:$O8))=0, "-", SUMPRODUCT(('Matriz Criterios'!$H$9:$S$9="X")*ISNUMBER('Registro Notas'!$D8:$O8)*'Registro Notas'!$D8:$O8)/SUMPRODUCT(('Matriz Criterios'!$H$9:$S$9="X")*ISNUMBER('Registro Notas'!$D8:$O8))) | G8: =IF(SUMPRODUCT(('Matriz Criterios'!$H$10:$S$10="X")*ISNUMBER('Registro Notas'!$D8:$O8))=0, "-", SUMPRODUCT(('Matriz Criterios'!$H$10:$S$10="X")*ISNUMBER('Registro Notas'!$D8:$O8)*'Registro Notas'!$D8:$O8)/SUMPRODUCT(('Matriz Criterios'!$H$10:$S$10="X")*ISNUMBER('Registro Notas'!$D8:$O8))) | H8: =IF(SUMPRODUCT(('Matriz Criterios'!$H$11:$S$11="X")*ISNUMBER('Registro Notas'!$D8:$O8))=0, "-", SUMPRODUCT(('Matriz Criterios'!$H$11:$S$11="X")*ISNUMBER('Registro Notas'!$D8:$O8)*'Registro Notas'!$D8:$O8)/SUMPRODUCT(('Matriz Criterios'!$H$11:$S$11="X")*ISNUMBER('Registro Notas'!$D8:$O8))) | I8: =IF(SUMPRODUCT(('Matriz Criterios'!$H$12:$S$12="X")*ISNUMBER('Registro Notas'!$D8:$O8))=0, "-", SUMPRODUCT(('Matriz Criterios'!$H$12:$S$12="X")*ISNUMBER('Registro Notas'!$D8:$O8)*'Registro Notas'!$D8:$O8)/SUMPRODUCT(('Matriz Criterios'!$H$12:$S$12="X")*ISNUMBER('Registro Notas'!$D8:$O8))) | J8: =IF(SUMPRODUCT(('Matriz Criterios'!$H$13:$S$13="X")*ISNUMBER('Registro Notas'!$D8:$O8))=0, "-", SUMPRODUCT(('Matriz Criterios'!$H$13:$S$13="X")*ISNUMBER('Registro Notas'!$D8:$O8)*'Registro Notas'!$D8:$O8)/SUMPRODUCT(('Matriz Criterios'!$H$13:$S$13="X")*ISNUMBER('Registro Notas'!$D8:$O8))) | K8: =IF(SUMPRODUCT(('Matriz Criterios'!$H$14:$S$14="X")*ISNUMBER('Registro Notas'!$D8:$O8))=0, "-", SUMPRODUCT(('Matriz Criterios'!$H$14:$S$14="X")*ISNUMBER('Registro Notas'!$D8:$O8)*'Registro Notas'!$D8:$O8)/SUMPRODUCT(('Matriz Criterios'!$H$14:$S$14="X")*ISNUMBER('Registro Notas'!$D8:$O8))) | L8: =IF(SUMPRODUCT(('Matriz Criterios'!$H$15:$S$15="X")*ISNUMBER('Registro Notas'!$D8:$O8))=0, "-", SUMPRODUCT(('Matriz Criterios'!$H$15:$S$15="X")*ISNUMBER('Registro Notas'!$D8:$O8)*'Registro Notas'!$D8:$O8)/SUMPRODUCT(('Matriz Criterios'!$H$15:$S$15="X")*ISNUMBER('Registro Notas'!$D8:$O8))) | M8: =IF(SUMPRODUCT(('Matriz Criterios'!$H$16:$S$16="X")*ISNUMBER('Registro Notas'!$D8:$O8))=0, "-", SUMPRODUCT(('Matriz Criterios'!$H$16:$S$16="X")*ISNUMBER('Registro Notas'!$D8:$O8)*'Registro Notas'!$D8:$O8)/SUMPRODUCT(('Matriz Criterios'!$H$16:$S$16="X")*ISNUMBER('Registro Notas'!$D8:$O8))) | N8: =IF(SUMPRODUCT(('Matriz Criterios'!$H$17:$S$17="X")*ISNUMBER('Registro Notas'!$D8:$O8))=0, "-", SUMPRODUCT(('Matriz Criterios'!$H$17:$S$17="X")*ISNUMBER('Registro Notas'!$D8:$O8)*'Registro Notas'!$D8:$O8)/SUMPRODUCT(('Matriz Criterios'!$H$17:$S$17="X")*ISNUMBER('Registro Notas'!$D8:$O8))) | O8: =IF(SUMPRODUCT(('Matriz Criterios'!$H$18:$S$18="X")*ISNUMBER('Registro Notas'!$D8:$O8))=0, "-", SUMPRODUCT(('Matriz Criterios'!$H$18:$S$18="X")*ISNUMBER('Registro Notas'!$D8:$O8)*'Registro Notas'!$D8:$O8)/SUMPRODUCT(('Matriz Criterios'!$H$18:$S$18="X")*ISNUMBER('Registro Notas'!$D8:$O8))) | P8: =IF(SUMPRODUCT(('Matriz Criterios'!$H$19:$S$19="X")*ISNUMBER('Registro Notas'!$D8:$O8))=0, "-", SUMPRODUCT(('Matriz Criterios'!$H$19:$S$19="X")*ISNUMBER('Registro Notas'!$D8:$O8)*'Registro Notas'!$D8:$O8)/SUMPRODUCT(('Matriz Criterios'!$H$19:$S$19="X")*ISNUMBER('Registro Notas'!$D8:$O8))) | Q8: =IF(SUMPRODUCT(('Matriz Criterios'!$H$20:$S$20="X")*ISNUMBER('Registro Notas'!$D8:$O8))=0, "-", SUMPRODUCT(('Matriz Criterios'!$H$20:$S$20="X")*ISNUMBER('Registro Notas'!$D8:$O8)*'Registro Notas'!$D8:$O8)/SUMPRODUCT(('Matriz Criterios'!$H$20:$S$20="X")*ISNUMBER('Registro Notas'!$D8:$O8))) | R8: =IF(SUMPRODUCT(('Matriz Criterios'!$H$21:$S$21="X")*ISNUMBER('Registro Notas'!$D8:$O8))=0, "-", SUMPRODUCT(('Matriz Criterios'!$H$21:$S$21="X")*ISNUMBER('Registro Notas'!$D8:$O8)*'Registro Notas'!$D8:$O8)/SUMPRODUCT(('Matriz Criterios'!$H$21:$S$21="X")*ISNUMBER('Registro Notas'!$D8:$O8))) | S8: =IF(SUMPRODUCT(('Matriz Criterios'!$H$22:$S$22="X")*ISNUMBER('Registro Notas'!$D8:$O8))=0, "-", SUMPRODUCT(('Matriz Criterios'!$H$22:$S$22="X")*ISNUMBER('Registro Notas'!$D8:$O8)*'Registro Notas'!$D8:$O8)/SUMPRODUCT(('Matriz Criterios'!$H$22:$S$22="X")*ISNUMBER('Registro Notas'!$D8:$O8))) | T8: =IF(SUMPRODUCT(('Matriz Criterios'!$H$23:$S$23="X")*ISNUMBER('Registro Notas'!$D8:$O8))=0, "-", SUMPRODUCT(('Matriz Criterios'!$H$23:$S$23="X")*ISNUMBER('Registro Notas'!$D8:$O8)*'Registro Notas'!$D8:$O8)/SUMPRODUCT(('Matriz Criterios'!$H$23:$S$23="X")*ISNUMBER('Registro Notas'!$D8:$O8))) | U8: =IF(SUMPRODUCT(('Matriz Criterios'!$H$24:$S$24="X")*ISNUMBER('Registro Notas'!$D8:$O8))=0, "-", SUMPRODUCT(('Matriz Criterios'!$H$24:$S$24="X")*ISNUMBER('Registro Notas'!$D8:$O8)*'Registro Notas'!$D8:$O8)/SUMPRODUCT(('Matriz Criterios'!$H$24:$S$24="X")*ISNUMBER('Registro Notas'!$D8:$O8))) | V8: =IF(SUMPRODUCT(('Matriz Criterios'!$H$25:$S$25="X")*ISNUMBER('Registro Notas'!$D8:$O8))=0, "-", SUMPRODUCT(('Matriz Criterios'!$H$25:$S$25="X")*ISNUMBER('Registro Notas'!$D8:$O8)*'Registro Notas'!$D8:$O8)/SUMPRODUCT(('Matriz Criterios'!$H$25:$S$25="X")*ISNUMBER('Registro Notas'!$D8:$O8))) | W8: =IF(SUMPRODUCT(('Matriz Criterios'!$H$26:$S$26="X")*ISNUMBER('Registro Notas'!$D8:$O8))=0, "-", SUMPRODUCT(('Matriz Criterios'!$H$26:$S$26="X")*ISNUMBER('Registro Notas'!$D8:$O8)*'Registro Notas'!$D8:$O8)/SUMPRODUCT(('Matriz Criterios'!$H$26:$S$26="X")*ISNUMBER('Registro Notas'!$D8:$O8))) | X8: =IF(SUMPRODUCT(('Matriz Criterios'!$H$27:$S$27="X")*ISNUMBER('Registro Notas'!$D8:$O8))=0, "-", SUMPRODUCT(('Matriz Criterios'!$H$27:$S$27="X")*ISNUMBER('Registro Notas'!$D8:$O8)*'Registro Notas'!$D8:$O8)/SUMPRODUCT(('Matriz Criterios'!$H$27:$S$27="X")*ISNUMBER('Registro Notas'!$D8:$O8))) | Y8: =IF(SUMPRODUCT(('Matriz Criterios'!$H$28:$S$28="X")*ISNUMBER('Registro Notas'!$D8:$O8))=0, "-", SUMPRODUCT(('Matriz Criterios'!$H$28:$S$28="X")*ISNUMBER('Registro Notas'!$D8:$O8)*'Registro Notas'!$D8:$O8)/SUMPRODUCT(('Matriz Criterios'!$H$28:$S$28="X")*ISNUMBER('Registro Notas'!$D8:$O8))) | Z8: =IF(SUMPRODUCT(('Matriz Criterios'!$H$29:$S$29="X")*ISNUMBER('Registro Notas'!$D8:$O8))=0, "-", SUMPRODUCT(('Matriz Criterios'!$H$29:$S$29="X")*ISNUMBER('Registro Notas'!$D8:$O8)*'Registro Notas'!$D8:$O8)/SUMPRODUCT(('Matriz Criterios'!$H$29:$S$29="X")*ISNUMBER('Registro Notas'!$D8:$O8))) | AA8: =IF(SUMPRODUCT(('Matriz Criterios'!$H$30:$S$30="X")*ISNUMBER('Registro Notas'!$D8:$O8))=0, "-", SUMPRODUCT(('Matriz Criterios'!$H$30:$S$30="X")*ISNUMBER('Registro Notas'!$D8:$O8)*'Registro Notas'!$D8:$O8)/SUMPRODUCT(('Matriz Criterios'!$H$30:$S$30="X")*ISNUMBER('Registro Notas'!$D8:$O8))) | AB8: =IF(SUMPRODUCT(('Matriz Criterios'!$H$31:$S$31="X")*ISNUMBER('Registro Notas'!$D8:$O8))=0, "-", SUMPRODUCT(('Matriz Criterios'!$H$31:$S$31="X")*ISNUMBER('Registro Notas'!$D8:$O8)*'Registro Notas'!$D8:$O8)/SUMPRODUCT(('Matriz Criterios'!$H$31:$S$31="X")*ISNUMBER('Registro Notas'!$D8:$O8))) | AC8: =IF(SUMPRODUCT(('Matriz Criterios'!$H$32:$S$32="X")*ISNUMBER('Registro Notas'!$D8:$O8))=0, "-", SUMPRODUCT(('Matriz Criterios'!$H$32:$S$32="X")*ISNUMBER('Registro Notas'!$D8:$O8)*'Registro Notas'!$D8:$O8)/SUMPRODUCT(('Matriz Criterios'!$H$32:$S$32="X")*ISNUMBER('Registro Notas'!$D8:$O8))) | AD8: =IF(SUMPRODUCT(('Matriz Criterios'!$H$33:$S$33="X")*ISNUMBER('Registro Notas'!$D8:$O8))=0, "-", SUMPRODUCT(('Matriz Criterios'!$H$33:$S$33="X")*ISNUMBER('Registro Notas'!$D8:$O8)*'Registro Notas'!$D8:$O8)/SUMPRODUCT(('Matriz Criterios'!$H$33:$S$33="X")*ISNUMBER('Registro Notas'!$D8:$O8))) | AE8: =IF(SUMPRODUCT(('Matriz Criterios'!$H$34:$S$34="X")*ISNUMBER('Registro Notas'!$D8:$O8))=0, "-", SUMPRODUCT(('Matriz Criterios'!$H$34:$S$34="X")*ISNUMBER('Registro Notas'!$D8:$O8)*'Registro Notas'!$D8:$O8)/SUMPRODUCT(('Matriz Criterios'!$H$34:$S$34="X")*ISNUMBER('Registro Notas'!$D8:$O8))) | AF8: =IF(SUMPRODUCT(('Matriz Criterios'!$H$35:$S$35="X")*ISNUMBER('Registro Notas'!$D8:$O8))=0, "-", SUMPRODUCT(('Matriz Criterios'!$H$35:$S$35="X")*ISNUMBER('Registro Notas'!$D8:$O8)*'Registro Notas'!$D8:$O8)/SUMPRODUCT(('Matriz Criterios'!$H$35:$S$35="X")*ISNUMBER('Registro Notas'!$D8:$O8))) | AG8: =IF(SUMPRODUCT(('Matriz Criterios'!$H$36:$S$36="X")*ISNUMBER('Registro Notas'!$D8:$O8))=0, "-", SUMPRODUCT(('Matriz Criterios'!$H$36:$S$36="X")*ISNUMBER('Registro Notas'!$D8:$O8)*'Registro Notas'!$D8:$O8)/SUMPRODUCT(('Matriz Criterios'!$H$36:$S$36="X")*ISNUMBER('Registro Notas'!$D8:$O8))) | AH8: =IF(SUMPRODUCT(('Matriz Criterios'!$H$37:$S$37="X")*ISNUMBER('Registro Notas'!$D8:$O8))=0, "-", SUMPRODUCT(('Matriz Criterios'!$H$37:$S$37="X")*ISNUMBER('Registro Notas'!$D8:$O8)*'Registro Notas'!$D8:$O8)/SUMPRODUCT(('Matriz Criterios'!$H$37:$S$37="X")*ISNUMBER('Registro Notas'!$D8:$O8))) | AI8: =IF(SUMPRODUCT(('Matriz Criterios'!$H$38:$S$38="X")*ISNUMBER('Registro Notas'!$D8:$O8))=0, "-", SUMPRODUCT(('Matriz Criterios'!$H$38:$S$38="X")*ISNUMBER('Registro Notas'!$D8:$O8)*'Registro Notas'!$D8:$O8)/SUMPRODUCT(('Matriz Criterios'!$H$38:$S$38="X")*ISNUMBER('Registro Notas'!$D8:$O8))) | AJ8: =IF(SUMPRODUCT(('Matriz Criterios'!$H$39:$S$39="X")*ISNUMBER('Registro Notas'!$D8:$O8))=0, "-", SUMPRODUCT(('Matriz Criterios'!$H$39:$S$39="X")*ISNUMBER('Registro Notas'!$D8:$O8)*'Registro Notas'!$D8:$O8)/SUMPRODUCT(('Matriz Criterios'!$H$39:$S$39="X")*ISNUMBER('Registro Notas'!$D8:$O8))) | AK8: =AVERAGE(C8:AJ8) | AL8: =COUNTIF(C8:AJ8, ">=5")
A9: 4 | B9: Delgado Santos, Alejandro | C9: =IF(SUMPRODUCT(('Matriz Criterios'!$H$6:$S$6="X")*ISNUMBER('Registro Notas'!$D9:$O9))=0, "-", SUMPRODUCT(('Matriz Criterios'!$H$6:$S$6="X")*ISNUMBER('Registro Notas'!$D9:$O9)*'Registro Notas'!$D9:$O9)/SUMPRODUCT(('Matriz Criterios'!$H$6:$S$6="X")*ISNUMBER('Registro Notas'!$D9:$O9))) | D9: =IF(SUMPRODUCT(('Matriz Criterios'!$H$7:$S$7="X")*ISNUMBER('Registro Notas'!$D9:$O9))=0, "-", SUMPRODUCT(('Matriz Criterios'!$H$7:$S$7="X")*ISNUMBER('Registro Notas'!$D9:$O9)*'Registro Notas'!$D9:$O9)/SUMPRODUCT(('Matriz Criterios'!$H$7:$S$7="X")*ISNUMBER('Registro Notas'!$D9:$O9))) | E9: =IF(SUMPRODUCT(('Matriz Criterios'!$H$8:$S$8="X")*ISNUMBER('Registro Notas'!$D9:$O9))=0, "-", SUMPRODUCT(('Matriz Criterios'!$H$8:$S$8="X")*ISNUMBER('Registro Notas'!$D9:$O9)*'Registro Notas'!$D9:$O9)/SUMPRODUCT(('Matriz Criterios'!$H$8:$S$8="X")*ISNUMBER('Registro Notas'!$D9:$O9))) | F9: =IF(SUMPRODUCT(('Matriz Criterios'!$H$9:$S$9="X")*ISNUMBER('Registro Notas'!$D9:$O9))=0, "-", SUMPRODUCT(('Matriz Criterios'!$H$9:$S$9="X")*ISNUMBER('Registro Notas'!$D9:$O9)*'Registro Notas'!$D9:$O9)/SUMPRODUCT(('Matriz Criterios'!$H$9:$S$9="X")*ISNUMBER('Registro Notas'!$D9:$O9))) | G9: =IF(SUMPRODUCT(('Matriz Criterios'!$H$10:$S$10="X")*ISNUMBER('Registro Notas'!$D9:$O9))=0, "-", SUMPRODUCT(('Matriz Criterios'!$H$10:$S$10="X")*ISNUMBER('Registro Notas'!$D9:$O9)*'Registro Notas'!$D9:$O9)/SUMPRODUCT(('Matriz Criterios'!$H$10:$S$10="X")*ISNUMBER('Registro Notas'!$D9:$O9))) | H9: =IF(SUMPRODUCT(('Matriz Criterios'!$H$11:$S$11="X")*ISNUMBER('Registro Notas'!$D9:$O9))=0, "-", SUMPRODUCT(('Matriz Criterios'!$H$11:$S$11="X")*ISNUMBER('Registro Notas'!$D9:$O9)*'Registro Notas'!$D9:$O9)/SUMPRODUCT(('Matriz Criterios'!$H$11:$S$11="X")*ISNUMBER('Registro Notas'!$D9:$O9))) | I9: =IF(SUMPRODUCT(('Matriz Criterios'!$H$12:$S$12="X")*ISNUMBER('Registro Notas'!$D9:$O9))=0, "-", SUMPRODUCT(('Matriz Criterios'!$H$12:$S$12="X")*ISNUMBER('Registro Notas'!$D9:$O9)*'Registro Notas'!$D9:$O9)/SUMPRODUCT(('Matriz Criterios'!$H$12:$S$12="X")*ISNUMBER('Registro Notas'!$D9:$O9))) | J9: =IF(SUMPRODUCT(('Matriz Criterios'!$H$13:$S$13="X")*ISNUMBER('Registro Notas'!$D9:$O9))=0, "-", SUMPRODUCT(('Matriz Criterios'!$H$13:$S$13="X")*ISNUMBER('Registro Notas'!$D9:$O9)*'Registro Notas'!$D9:$O9)/SUMPRODUCT(('Matriz Criterios'!$H$13:$S$13="X")*ISNUMBER('Registro Notas'!$D9:$O9))) | K9: =IF(SUMPRODUCT(('Matriz Criterios'!$H$14:$S$14="X")*ISNUMBER('Registro Notas'!$D9:$O9))=0, "-", SUMPRODUCT(('Matriz Criterios'!$H$14:$S$14="X")*ISNUMBER('Registro Notas'!$D9:$O9)*'Registro Notas'!$D9:$O9)/SUMPRODUCT(('Matriz Criterios'!$H$14:$S$14="X")*ISNUMBER('Registro Notas'!$D9:$O9))) | L9: =IF(SUMPRODUCT(('Matriz Criterios'!$H$15:$S$15="X")*ISNUMBER('Registro Notas'!$D9:$O9))=0, "-", SUMPRODUCT(('Matriz Criterios'!$H$15:$S$15="X")*ISNUMBER('Registro Notas'!$D9:$O9)*'Registro Notas'!$D9:$O9)/SUMPRODUCT(('Matriz Criterios'!$H$15:$S$15="X")*ISNUMBER('Registro Notas'!$D9:$O9))) | M9: =IF(SUMPRODUCT(('Matriz Criterios'!$H$16:$S$16="X")*ISNUMBER('Registro Notas'!$D9:$O9))=0, "-", SUMPRODUCT(('Matriz Criterios'!$H$16:$S$16="X")*ISNUMBER('Registro Notas'!$D9:$O9)*'Registro Notas'!$D9:$O9)/SUMPRODUCT(('Matriz Criterios'!$H$16:$S$16="X")*ISNUMBER('Registro Notas'!$D9:$O9))) | N9: =IF(SUMPRODUCT(('Matriz Criterios'!$H$17:$S$17="X")*ISNUMBER('Registro Notas'!$D9:$O9))=0, "-", SUMPRODUCT(('Matriz Criterios'!$H$17:$S$17="X")*ISNUMBER('Registro Notas'!$D9:$O9)*'Registro Notas'!$D9:$O9)/SUMPRODUCT(('Matriz Criterios'!$H$17:$S$17="X")*ISNUMBER('Registro Notas'!$D9:$O9))) | O9: =IF(SUMPRODUCT(('Matriz Criterios'!$H$18:$S$18="X")*ISNUMBER('Registro Notas'!$D9:$O9))=0, "-", SUMPRODUCT(('Matriz Criterios'!$H$18:$S$18="X")*ISNUMBER('Registro Notas'!$D9:$O9)*'Registro Notas'!$D9:$O9)/SUMPRODUCT(('Matriz Criterios'!$H$18:$S$18="X")*ISNUMBER('Registro Notas'!$D9:$O9))) | P9: =IF(SUMPRODUCT(('Matriz Criterios'!$H$19:$S$19="X")*ISNUMBER('Registro Notas'!$D9:$O9))=0, "-", SUMPRODUCT(('Matriz Criterios'!$H$19:$S$19="X")*ISNUMBER('Registro Notas'!$D9:$O9)*'Registro Notas'!$D9:$O9)/SUMPRODUCT(('Matriz Criterios'!$H$19:$S$19="X")*ISNUMBER('Registro Notas'!$D9:$O9))) | Q9: =IF(SUMPRODUCT(('Matriz Criterios'!$H$20:$S$20="X")*ISNUMBER('Registro Notas'!$D9:$O9))=0, "-", SUMPRODUCT(('Matriz Criterios'!$H$20:$S$20="X")*ISNUMBER('Registro Notas'!$D9:$O9)*'Registro Notas'!$D9:$O9)/SUMPRODUCT(('Matriz Criterios'!$H$20:$S$20="X")*ISNUMBER('Registro Notas'!$D9:$O9))) | R9: =IF(SUMPRODUCT(('Matriz Criterios'!$H$21:$S$21="X")*ISNUMBER('Registro Notas'!$D9:$O9))=0, "-", SUMPRODUCT(('Matriz Criterios'!$H$21:$S$21="X")*ISNUMBER('Registro Notas'!$D9:$O9)*'Registro Notas'!$D9:$O9)/SUMPRODUCT(('Matriz Criterios'!$H$21:$S$21="X")*ISNUMBER('Registro Notas'!$D9:$O9))) | S9: =IF(SUMPRODUCT(('Matriz Criterios'!$H$22:$S$22="X")*ISNUMBER('Registro Notas'!$D9:$O9))=0, "-", SUMPRODUCT(('Matriz Criterios'!$H$22:$S$22="X")*ISNUMBER('Registro Notas'!$D9:$O9)*'Registro Notas'!$D9:$O9)/SUMPRODUCT(('Matriz Criterios'!$H$22:$S$22="X")*ISNUMBER('Registro Notas'!$D9:$O9))) | T9: =IF(SUMPRODUCT(('Matriz Criterios'!$H$23:$S$23="X")*ISNUMBER('Registro Notas'!$D9:$O9))=0, "-", SUMPRODUCT(('Matriz Criterios'!$H$23:$S$23="X")*ISNUMBER('Registro Notas'!$D9:$O9)*'Registro Notas'!$D9:$O9)/SUMPRODUCT(('Matriz Criterios'!$H$23:$S$23="X")*ISNUMBER('Registro Notas'!$D9:$O9))) | U9: =IF(SUMPRODUCT(('Matriz Criterios'!$H$24:$S$24="X")*ISNUMBER('Registro Notas'!$D9:$O9))=0, "-", SUMPRODUCT(('Matriz Criterios'!$H$24:$S$24="X")*ISNUMBER('Registro Notas'!$D9:$O9)*'Registro Notas'!$D9:$O9)/SUMPRODUCT(('Matriz Criterios'!$H$24:$S$24="X")*ISNUMBER('Registro Notas'!$D9:$O9))) | V9: =IF(SUMPRODUCT(('Matriz Criterios'!$H$25:$S$25="X")*ISNUMBER('Registro Notas'!$D9:$O9))=0, "-", SUMPRODUCT(('Matriz Criterios'!$H$25:$S$25="X")*ISNUMBER('Registro Notas'!$D9:$O9)*'Registro Notas'!$D9:$O9)/SUMPRODUCT(('Matriz Criterios'!$H$25:$S$25="X")*ISNUMBER('Registro Notas'!$D9:$O9))) | W9: =IF(SUMPRODUCT(('Matriz Criterios'!$H$26:$S$26="X")*ISNUMBER('Registro Notas'!$D9:$O9))=0, "-", SUMPRODUCT(('Matriz Criterios'!$H$26:$S$26="X")*ISNUMBER('Registro Notas'!$D9:$O9)*'Registro Notas'!$D9:$O9)/SUMPRODUCT(('Matriz Criterios'!$H$26:$S$26="X")*ISNUMBER('Registro Notas'!$D9:$O9))) | X9: =IF(SUMPRODUCT(('Matriz Criterios'!$H$27:$S$27="X")*ISNUMBER('Registro Notas'!$D9:$O9))=0, "-", SUMPRODUCT(('Matriz Criterios'!$H$27:$S$27="X")*ISNUMBER('Registro Notas'!$D9:$O9)*'Registro Notas'!$D9:$O9)/SUMPRODUCT(('Matriz Criterios'!$H$27:$S$27="X")*ISNUMBER('Registro Notas'!$D9:$O9))) | Y9: =IF(SUMPRODUCT(('Matriz Criterios'!$H$28:$S$28="X")*ISNUMBER('Registro Notas'!$D9:$O9))=0, "-", SUMPRODUCT(('Matriz Criterios'!$H$28:$S$28="X")*ISNUMBER('Registro Notas'!$D9:$O9)*'Registro Notas'!$D9:$O9)/SUMPRODUCT(('Matriz Criterios'!$H$28:$S$28="X")*ISNUMBER('Registro Notas'!$D9:$O9))) | Z9: =IF(SUMPRODUCT(('Matriz Criterios'!$H$29:$S$29="X")*ISNUMBER('Registro Notas'!$D9:$O9))=0, "-", SUMPRODUCT(('Matriz Criterios'!$H$29:$S$29="X")*ISNUMBER('Registro Notas'!$D9:$O9)*'Registro Notas'!$D9:$O9)/SUMPRODUCT(('Matriz Criterios'!$H$29:$S$29="X")*ISNUMBER('Registro Notas'!$D9:$O9))) | AA9: =IF(SUMPRODUCT(('Matriz Criterios'!$H$30:$S$30="X")*ISNUMBER('Registro Notas'!$D9:$O9))=0, "-", SUMPRODUCT(('Matriz Criterios'!$H$30:$S$30="X")*ISNUMBER('Registro Notas'!$D9:$O9)*'Registro Notas'!$D9:$O9)/SUMPRODUCT(('Matriz Criterios'!$H$30:$S$30="X")*ISNUMBER('Registro Notas'!$D9:$O9))) | AB9: =IF(SUMPRODUCT(('Matriz Criterios'!$H$31:$S$31="X")*ISNUMBER('Registro Notas'!$D9:$O9))=0, "-", SUMPRODUCT(('Matriz Criterios'!$H$31:$S$31="X")*ISNUMBER('Registro Notas'!$D9:$O9)*'Registro Notas'!$D9:$O9)/SUMPRODUCT(('Matriz Criterios'!$H$31:$S$31="X")*ISNUMBER('Registro Notas'!$D9:$O9))) | AC9: =IF(SUMPRODUCT(('Matriz Criterios'!$H$32:$S$32="X")*ISNUMBER('Registro Notas'!$D9:$O9))=0, "-", SUMPRODUCT(('Matriz Criterios'!$H$32:$S$32="X")*ISNUMBER('Registro Notas'!$D9:$O9)*'Registro Notas'!$D9:$O9)/SUMPRODUCT(('Matriz Criterios'!$H$32:$S$32="X")*ISNUMBER('Registro Notas'!$D9:$O9))) | AD9: =IF(SUMPRODUCT(('Matriz Criterios'!$H$33:$S$33="X")*ISNUMBER('Registro Notas'!$D9:$O9))=0, "-", SUMPRODUCT(('Matriz Criterios'!$H$33:$S$33="X")*ISNUMBER('Registro Notas'!$D9:$O9)*'Registro Notas'!$D9:$O9)/SUMPRODUCT(('Matriz Criterios'!$H$33:$S$33="X")*ISNUMBER('Registro Notas'!$D9:$O9))) | AE9: =IF(SUMPRODUCT(('Matriz Criterios'!$H$34:$S$34="X")*ISNUMBER('Registro Notas'!$D9:$O9))=0, "-", SUMPRODUCT(('Matriz Criterios'!$H$34:$S$34="X")*ISNUMBER('Registro Notas'!$D9:$O9)*'Registro Notas'!$D9:$O9)/SUMPRODUCT(('Matriz Criterios'!$H$34:$S$34="X")*ISNUMBER('Registro Notas'!$D9:$O9))) | AF9: =IF(SUMPRODUCT(('Matriz Criterios'!$H$35:$S$35="X")*ISNUMBER('Registro Notas'!$D9:$O9))=0, "-", SUMPRODUCT(('Matriz Criterios'!$H$35:$S$35="X")*ISNUMBER('Registro Notas'!$D9:$O9)*'Registro Notas'!$D9:$O9)/SUMPRODUCT(('Matriz Criterios'!$H$35:$S$35="X")*ISNUMBER('Registro Notas'!$D9:$O9))) | AG9: =IF(SUMPRODUCT(('Matriz Criterios'!$H$36:$S$36="X")*ISNUMBER('Registro Notas'!$D9:$O9))=0, "-", SUMPRODUCT(('Matriz Criterios'!$H$36:$S$36="X")*ISNUMBER('Registro Notas'!$D9:$O9)*'Registro Notas'!$D9:$O9)/SUMPRODUCT(('Matriz Criterios'!$H$36:$S$36="X")*ISNUMBER('Registro Notas'!$D9:$O9))) | AH9: =IF(SUMPRODUCT(('Matriz Criterios'!$H$37:$S$37="X")*ISNUMBER('Registro Notas'!$D9:$O9))=0, "-", SUMPRODUCT(('Matriz Criterios'!$H$37:$S$37="X")*ISNUMBER('Registro Notas'!$D9:$O9)*'Registro Notas'!$D9:$O9)/SUMPRODUCT(('Matriz Criterios'!$H$37:$S$37="X")*ISNUMBER('Registro Notas'!$D9:$O9))) | AI9: =IF(SUMPRODUCT(('Matriz Criterios'!$H$38:$S$38="X")*ISNUMBER('Registro Notas'!$D9:$O9))=0, "-", SUMPRODUCT(('Matriz Criterios'!$H$38:$S$38="X")*ISNUMBER('Registro Notas'!$D9:$O9)*'Registro Notas'!$D9:$O9)/SUMPRODUCT(('Matriz Criterios'!$H$38:$S$38="X")*ISNUMBER('Registro Notas'!$D9:$O9))) | AJ9: =IF(SUMPRODUCT(('Matriz Criterios'!$H$39:$S$39="X")*ISNUMBER('Registro Notas'!$D9:$O9))=0, "-", SUMPRODUCT(('Matriz Criterios'!$H$39:$S$39="X")*ISNUMBER('Registro Notas'!$D9:$O9)*'Registro Notas'!$D9:$O9)/SUMPRODUCT(('Matriz Criterios'!$H$39:$S$39="X")*ISNUMBER('Registro Notas'!$D9:$O9))) | AK9: =AVERAGE(C9:AJ9) | AL9: =COUNTIF(C9:AJ9, ">=5")
